Workbook

Sheet Assumptions
B2: HVAC Service Company — Financial Model Assumptions
B4: BASELINE ASSUMPTIONS
C6: $1M Tier | D6: $2.5M Tier | E6: $5M Tier
B7: Revenue
B8: Total Revenue | C8: 1000000 | D8: 2500000 | E8: 5000000
B9: Residential Service & Repair (%) | C9: 0.45 | D9: 0.35 | E9: 0.25
B10: Commercial Service & Repair (%) | C10: 0.2 | D10: 0.25 | E10: 0.3
B11: Maintenance Contracts (%) | C11: 0.15 | D11: 0.2 | E11: 0.25
B12: New Installations (%) | C12: 0.2 | D12: 0.2 | E12: 0.2
B14: Cost of Revenue
B15: Technician Labor (% of Rev) | C15: 0.3 | D15: 0.28 | E15: 0.26
B16: Parts & Materials (% of Rev) | C16: 0.18 | D16: 0.17 | E16: 0.16
B17: Vehicle & Equipment (% of Rev) | C17: 0.05 | D17: 0.045 | E17: 0.04
B18: Subcontractors (% of Rev) | C18: 0.02 | D18: 0.03 | E18: 0.04
B20: Sales & Marketing
B21: Sales Staff & Commissions (% of Rev) | C21: 0.04 | D21: 0.045 | E21: 0.05
B22: Advertising & Lead Gen (% of Rev) | C22: 0.05 | D22: 0.045 | E22: 0.04
B23: Website & Digital Marketing (% of Rev) | C23: 0.015 | D23: 0.012 | E23: 0.01
B24: Referral Programs (% of Rev) | C24: 0.005 | D24: 0.008 | E24: 0.01
B26: General & Administrative
B27: Owner / GM Salary | C27: 120000 | D27: 160000 | E27: 200000
B28: Office & Admin Staff | C28: 45000 | D28: 95000 | E28: 160000
B29: Rent & Utilities (Low Fixed) | C29: 24000 | D29: 36000 | E29: 48000
B30: Insurance (GL, WC, Auto) | C30: 30000 | D30: 55000 | E30: 90000
B31: Software & IT | C31: 12000 | D31: 24000 | E31: 42000
B32: Accounting & Legal | C32: 15000 | D32: 25000 | E32: 40000
B33: Licenses, Permits, Training | C33: 8000 | D33: 15000 | E33: 25000
B34: Miscellaneous G&A | C34: 6000 | D34: 10000 | E34: 18000
B36: AI ENHANCEMENT ASSUMPTIONS
B37: AI tools are pre-built and deployed at minimal incremental cost. Savings come from automation of scheduling, dispatch, quoting, bookkeeping, CRM, and marketing.
C39: $1M Tier | D39: $2.5M Tier | E39: $5M Tier
B40: AI Impact on G&A
B41: Office & Admin Staff Reduction | C41: 0.5 | D41: 0.45 | E41: 0.4 | G41: AI handles scheduling, dispatch, invoicing, bookkeeping
B42: Software & IT Change | C42: 5000 | D42: 8000 | E42: 12000 | G42: Net: replace multiple tools with AI platform
B43: Accounting & Legal Reduction | C43: 0.3 | D43: 0.3 | E43: 0.25 | G43: AI-assisted bookkeeping, auto-categorization
B44: Misc G&A Reduction | C44: 0.2 | D44: 0.2 | E44: 0.2 | G44: General efficiency gains
B46: AI Impact on Sales & Marketing
B47: Sales Staff & Commissions Reduction | C47: 0.25 | D47: 0.2 | E47: 0.15 | G47: AI-powered CRM, auto follow-ups, lead scoring
B48: Advertising & Lead Gen Reduction | C48: 0.3 | D48: 0.25 | E48: 0.2 | G48: AI-optimized ad spend, better targeting
B49: Website & Digital Mktg Reduction | C49: 0.4 | D49: 0.4 | E49: 0.35 | G49: AI content generation, SEO, chatbot
...

Sheet Baseline P&L
B2: HVAC Service Company — Baseline P&L (No AI)
C4: $1M Tier | D4: % Rev | E4: $2.5M Tier | F4: % Rev | G4: $5M Tier | H4: % Rev
B6: Revenue | C6: =Assumptions!C8 -> 1000000 | D6: 1 | E6: =Assumptions!D8 -> 2500000 | F6: 1 | G6: =Assumptions!E8 -> 5000000 | H6: 1
B8: Cost of Revenue
B9: Technician Labor | C9: =Assumptions!C15*Assumptions!C8 -> 300000 | D9: =IF(C9=0,"-",C9/C$6) -> 0.3 | E9: =Assumptions!D15*Assumptions!D8 -> 700000 | F9: =IF(E9=0,"-",E9/E$6) -> 0.28 | G9: =Assumptions!E15*Assumptions!E8 -> 1300000 | H9: =IF(G9=0,"-",G9/G$6) -> 0.26
B10: Parts & Materials | C10: =Assumptions!C16*Assumptions!C8 -> 180000 | D10: =IF(C10=0,"-",C10/C$6) -> 0.18 | E10: =Assumptions!D16*Assumptions!D8 -> 425000 | F10: =IF(E10=0,"-",E10/E$6) -> 0.17 | G10: =Assumptions!E16*Assumptions!E8 -> 800000 | H10: =IF(G10=0,"-",G10/G$6) -> 0.16
B11: Vehicle & Equipment | C11: =Assumptions!C17*Assumptions!C8 -> 50000 | D11: =IF(C11=0,"-",C11/C$6) -> 0.05 | E11: =Assumptions!D17*Assumptions!D8 -> 112500 | F11: =IF(E11=0,"-",E11/E$6) -> 0.045 | G11: =Assumptions!E17*Assumptions!E8 -> 200000 | H11: =IF(G11=0,"-",G11/G$6) -> 0.04
B12: Subcontractors | C12: =Assumptions!C18*Assumptions!C8 -> 20000 | D12: =IF(C12=0,"-",C12/C$6) -> 0.02 | E12: =Assumptions!D18*Assumptions!D8 -> 75000 | F12: =IF(E12=0,"-",E12/E$6) -> 0.03 | G12: =Assumptions!E18*Assumptions!E8 -> 200000 | H12: =IF(G12=0,"-",G12/G$6) -> 0.04
B13: Total Cost of Revenue | C13: =SUM(C9:C12) -> 550000 | D13: =IF(C13=0,"-",C13/C$6) -> 0.55 | E13: =SUM(E9:E12) -> 1312500 | F13: =IF(E13=0,"-",E13/E$6) -> 0.525 | G13: =SUM(G9:G12) -> 2500000 | H13: =IF(G13=0,"-",G13/G$6) -> 0.5
B15: Gross Profit | C15: =C6-C13 -> 450000 | D15: =IF(C15=0,"-",C15/C$6) -> 0.45 | E15: =E6-E13 -> 1187500 | F15: =IF(E15=0,"-",E15/E$6) -> 0.475 | G15: =G6-G13 -> 2500000 | H15: =IF(G15=0,"-",G15/G$6) -> 0.5
B17: Sales & Marketing
B18: Sales Staff & Commissions | C18: =Assumptions!C21*Assumptions!C8 -> 40000 | D18: =IF(C18=0,"-",C18/C$6) -> 0.04 | E18: =Assumptions!D21*Assumptions!D8 -> 112500 | F18: =IF(E18=0,"-",E18/E$6) -> 0.045 | G18: =Assumptions!E21*Assumptions!E8 -> 250000 | H18: =IF(G18=0,"-",G18/G$6) -> 0.05
B19: Advertising & Lead Gen | C19: =Assumptions!C22*Assumptions!C8 -> 50000 | D19: =IF(C19=0,"-",C19/C$6) -> 0.05 | E19: =Assumptions!D22*Assumptions!D8 -> 112500 | F19: =IF(E19=0,"-",E19/E$6) -> 0.045 | G19: =Assumptions!E22*Assumptions!E8 -> 200000 | H19: =IF(G19=0,"-",G19/G$6) -> 0.04
B20: Website & Digital Marketing | C20: =Assumptions!C23*Assumptions!C8 -> 15000 | D20: =IF(C20=0,"-",C20/C$6) -> 0.015 | E20: =Assumptions!D23*Assumptions!D8 -> 30000 | F20: =IF(E20=0,"-",E20/E$6) -> 0.012 | G20: =Assumptions!E23*Assumptions!E8 -> 50000 | H20: =IF(G20=0,"-",G20/G$6) -> 0.01
B21: Referral Programs | C21: =Assumptions!C24*Assumptions!C8 -> 5000 | D21: =IF(C21=0,"-",C21/C$6) -> 0.005 | E21: =Assumptions!D24*Assumptions!D8 -> 20000 | F21: =IF(E21=0,"-",E21/E$6) -> 0.008 | G21: =Assumptions!E24*Assumptions!E8 -> 50000 | H21: =IF(G21=0,"-",G21/G$6) -> 0.01
B22: Total Sales & Marketing | C22: =SUM(C18:C21) -> 110000 | D22: =IF(C22=0,"-",C22/C$6) -> 0.11 | E22: =SUM(E18:E21) -> 275000 | F22: =IF(E22=0,"-",E22/E$6) -> 0.11 | G22: =SUM(G18:G21) -> 550000 | H22: =IF(G22=0,"-",G22/G$6) -> 0.11
B24: General & Administrative
B25: Owner / GM Salary | C25: =Assumptions!C27 -> 120000 | D25: =IF(C25=0,"-",C25/C$6) -> 0.12 | E25: =Assumptions!D27 -> 160000 | F25: =IF(E25=0,"-",E25/E$6) -> 0.064 | G25: =Assumptions!E27 -> 200000 | H25: =IF(G25=0,"-",G25/G$6) -> 0.04
B26: Office & Admin Staff | C26: =Assumptions!C28 -> 45000 | D26: =IF(C26=0,"-",C26/C$6) -> 0.045 | E26: =Assumptions!D28 -> 95000 | F26: =IF(E26=0,"-",E26/E$6) -> 0.038 | G26: =Assumptions!E28 -> 160000 | H26: =IF(G26=0,"-",G26/G$6) -> 0.032
B27: Rent & Utilities | C27: =Assumptions!C29 -> 24000 | D27: =IF(C27=0,"-",C27/C$6) -> 0.024 | E27: =Assumptions!D29 -> 36000 | F27: =IF(E27=0,"-",E27/E$6) -> 0.0144 | G27: =Assumptions!E29 -> 48000 | H27: =IF(G27=0,"-",G27/G$6) -> 0.0096
B28: Insurance | C28: =Assumptions!C30 -> 30000 | D28: =IF(C28=0,"-",C28/C$6) -> 0.03 | E28: =Assumptions!D30 -> 55000 | F28: =IF(E28=0,"-",E28/E$6) -> 0.022 | G28: =Assumptions!E30 -> 90000 | H28: =IF(G28=0,"-",G28/G$6) -> 0.018
B29: Software & IT | C29: =Assumptions!C31 -> 12000 | D29: =IF(C29=0,"-",C29/C$6) -> 0.012 | E29: =Assumptions!D31 -> 24000 | F29: =IF(E29=0,"-",E29/E$6) -> 0.0096 | G29: =Assumptions!E31 -> 42000 | H29: =IF(G29=0,"-",G29/G$6) -> 0.0084
B30: Accounting & Legal | C30: =Assumptions!C32 -> 15000 | D30: =IF(C30=0,"-",C30/C$6) -> 0.015 | E30: =Assumptions!D32 -> 25000 | F30: =IF(E30=0,"-",E30/E$6) -> 0.01 | G30: =Assumptions!E32 -> 40000 | H30: =IF(G30=0,"-",G30/G$6) -> 0.008
B31: Licenses, Permits, Training | C31: =Assumptions!C33 -> 8000 | D31: =IF(C31=0,"-",C31/C$6) -> 0.008 | E31: =Assumptions!D33 -> 15000 | F31: =IF(E31=0,"-",E31/E$6) -> 0.006 | G31: =Assumptions!E33 -> 25000 | H31: =IF(G31=0,"-",G31/G$6) -> 0.005
B32: Miscellaneous | C32: =Assumptions!C34 -> 6000 | D32: =IF(C32=0,"-",C32/C$6) -> 0.006 | E32: =Assumptions!D34 -> 10000 | F32: =IF(E32=0,"-",E32/E$6) -> 0.004 | G32: =Assumptions!E34 -> 18000 | H32: =IF(G32=0,"-",G32/G$6) -> 0.0036
B33: Total G&A | C33: =SUM(C25:C32) -> 260000 | D33: =IF(C33=0,"-",C33/C$6) -> 0.26 | E33: =SUM(E25:E32) -> 420000 | F33: =IF(E33=0,"-",E33/E$6) -> 0.168 | G33: =SUM(G25:G32) -> 623000 | H33: =IF(G33=0,"-",G33/G$6) -> 0.1246
B35: Total Operating Expenses | C35: =C13+C22+C33 -> 920000 | D35: =IF(C35=0,"-",C35/C$6) -> 0.92 | E35: =E13+E22+E33 -> 2007500 | F35: =IF(E35=0,"-",E35/E$6) -> 0.803 | G35: =G13+G22+G33 -> 3673000 | H35: =IF(G35=0,"-",G35/G$6) -> 0.7346
B37: EBITDA | C37: =C6-C35 -> 80000 | D37: =IF(C37=0,"-",C37/C$6) -> 0.08 | E37: =E6-E35 -> 492500 | F37: =IF(E37=0,"-",E37/E$6) -> 0.197 | G37: =G6-G35 -> 1327000 | H37: =IF(G37=0,"-",G37/G$6) -> 0.2654

Sheet AI-Enhanced P&L
B2: HVAC Service Company — AI-Enhanced P&L
B3: Leveraging AI for G&A automation and Sales & Marketing optimization
C4: $1M Tier | D4: % Rev | E4: $2.5M Tier | F4: % Rev | G4: $5M Tier | H4: % Rev
B6: Revenue (incl. AI referral uplift) | C6: =Assumptions!C8*(1+Assumptions!C50) -> 1005000 | D6: 1 | E6: =Assumptions!D8*(1+Assumptions!D50) -> 2512500 | F6: 1 | G6: =Assumptions!E8*(1+Assumptions!E50) -> 5025000 | H6: 1
B8: Cost of Revenue (unchanged)
B9: Technician Labor | C9: =Assumptions!C15*C6 -> 301500 | D9: =IF(C9=0,"-",C9/C$6) -> 0.3 | E9: =Assumptions!D15*E6 -> 703500 | F9: =IF(E9=0,"-",E9/E$6) -> 0.28 | G9: =Assumptions!E15*G6 -> 1306500 | H9: =IF(G9=0,"-",G9/G$6) -> 0.26
B10: Parts & Materials | C10: =Assumptions!C16*C6 -> 180900 | D10: =IF(C10=0,"-",C10/C$6) -> 0.18 | E10: =Assumptions!D16*E6 -> 427125 | F10: =IF(E10=0,"-",E10/E$6) -> 0.17 | G10: =Assumptions!E16*G6 -> 804000 | H10: =IF(G10=0,"-",G10/G$6) -> 0.16
B11: Vehicle & Equipment | C11: =Assumptions!C17*C6 -> 50250 | D11: =IF(C11=0,"-",C11/C$6) -> 0.05 | E11: =Assumptions!D17*E6 -> 113062.5 | F11: =IF(E11=0,"-",E11/E$6) -> 0.045 | G11: =Assumptions!E17*G6 -> 201000 | H11: =IF(G11=0,"-",G11/G$6) -> 0.04
B12: Subcontractors | C12: =Assumptions!C18*C6 -> 20100 | D12: =IF(C12=0,"-",C12/C$6) -> 0.02 | E12: =Assumptions!D18*E6 -> 75375 | F12: =IF(E12=0,"-",E12/E$6) -> 0.03 | G12: =Assumptions!E18*G6 -> 201000 | H12: =IF(G12=0,"-",G12/G$6) -> 0.04
B13: Total Cost of Revenue | C13: =SUM(C9:C12) -> 552750 | D13: =IF(C13=0,"-",C13/C$6) -> 0.55 | E13: =SUM(E9:E12) -> 1319062.5 | F13: =IF(E13=0,"-",E13/E$6) -> 0.525 | G13: =SUM(G9:G12) -> 2512500 | H13: =IF(G13=0,"-",G13/G$6) -> 0.5
B15: Gross Profit | C15: =C6-C13 -> 452250 | D15: =IF(C15=0,"-",C15/C$6) -> 0.45 | E15: =E6-E13 -> 1193437.5 | F15: =IF(E15=0,"-",E15/E$6) -> 0.475 | G15: =G6-G13 -> 2512500 | H15: =IF(G15=0,"-",G15/G$6) -> 0.5
B17: Sales & Marketing (AI-Optimized)
B18: Sales Staff & Commissions | C18: =Assumptions!C21*(1-Assumptions!C47)*C6 -> 30150 | D18: =IF(C18=0,"-",C18/C$6) -> 0.03 | E18: =Assumptions!D21*(1-Assumptions!D47)*E6 -> 90450 | F18: =IF(E18=0,"-",E18/E$6) -> 0.036 | G18: =Assumptions!E21*(1-Assumptions!E47)*G6 -> 213562.5 | H18: =IF(G18=0,"-",G18/G$6) -> 0.0425
B19: Advertising & Lead Gen | C19: =Assumptions!C22*(1-Assumptions!C48)*C6 -> 35175 | D19: =IF(C19=0,"-",C19/C$6) -> 0.035 | E19: =Assumptions!D22*(1-Assumptions!D48)*E6 -> 84796.875 | F19: =IF(E19=0,"-",E19/E$6) -> 0.03375 | G19: =Assumptions!E22*(1-Assumptions!E48)*G6 -> 160800 | H19: =IF(G19=0,"-",G19/G$6) -> 0.032
B20: Website & Digital Marketing | C20: =Assumptions!C23*(1-Assumptions!C49)*C6 -> 9045 | D20: =IF(C20=0,"-",C20/C$6) -> 0.009 | E20: =Assumptions!D23*(1-Assumptions!D49)*E6 -> 18090 | F20: =IF(E20=0,"-",E20/E$6) -> 0.0072 | G20: =Assumptions!E23*(1-Assumptions!E49)*G6 -> 32662.5 | H20: =IF(G20=0,"-",G20/G$6) -> 0.0065
B21: Referral Programs | C21: =Assumptions!C24*C6 -> 5025 | D21: =IF(C21=0,"-",C21/C$6) -> 0.005 | E21: =Assumptions!D24*E6 -> 20100 | F21: =IF(E21=0,"-",E21/E$6) -> 0.008 | G21: =Assumptions!E24*G6 -> 50250 | H21: =IF(G21=0,"-",G21/G$6) -> 0.01
B22: Total Sales & Marketing | C22: =SUM(C18:C21) -> 79395 | D22: =IF(C22=0,"-",C22/C$6) -> 0.079 | E22: =SUM(E18:E21) -> 213436.88 | F22: =IF(E22=0,"-",E22/E$6) -> 0.08495 | G22: =SUM(G18:G21) -> 457275 | H22: =IF(G22=0,"-",G22/G$6) -> 0.091
B24: General & Administrative (AI-Automated)
B25: Owner / GM Salary | C25: =Assumptions!C27 -> 120000 | D25: =IF(C25=0,"-",C25/C$6) -> 0.11940299 | E25: =Assumptions!D27 -> 160000 | F25: =IF(E25=0,"-",E25/E$6) -> 0.063681592 | G25: =Assumptions!E27 -> 200000 | H25: =IF(G25=0,"-",G25/G$6) -> 0.039800995
B26: Office & Admin Staff | C26: =Assumptions!C28*(1-Assumptions!C41) -> 22500 | D26: =IF(C26=0,"-",C26/C$6) -> 0.02238806 | E26: =Assumptions!D28*(1-Assumptions!D41) -> 52250 | F26: =IF(E26=0,"-",E26/E$6) -> 0.02079602 | G26: =Assumptions!E28*(1-Assumptions!E41) -> 96000 | H26: =IF(G26=0,"-",G26/G$6) -> 0.019104478
B27: Rent & Utilities | C27: =Assumptions!C29 -> 24000 | D27: =IF(C27=0,"-",C27/C$6) -> 0.023880597 | E27: =Assumptions!D29 -> 36000 | F27: =IF(E27=0,"-",E27/E$6) -> 0.014328358 | G27: =Assumptions!E29 -> 48000 | H27: =IF(G27=0,"-",G27/G$6) -> 0.0095522388
B28: Insurance | C28: =Assumptions!C30 -> 30000 | D28: =IF(C28=0,"-",C28/C$6) -> 0.029850746 | E28: =Assumptions!D30 -> 55000 | F28: =IF(E28=0,"-",E28/E$6) -> 0.021890547 | G28: =Assumptions!E30 -> 90000 | H28: =IF(G28=0,"-",G28/G$6) -> 0.017910448
B29: Software & IT (net of AI platform) | C29: =Assumptions!C31-Assumptions!C42+Assumptions!C53*12 -> 13000 | D29: =IF(C29=0,"-",C29/C$6) -> 0.012935323 | E29: =Assumptions!D31-Assumptions!D42+Assumptions!D53*12 -> 25000 | F29: =IF(E29=0,"-",E29/E$6) -> 0.0099502488 | G29: =Assumptions!E31-Assumptions!E42+Assumptions!E53*12 -> 42000 | H29: =IF(G29=0,"-",G29/G$6) -> 0.008358209
B30: Accounting & Legal | C30: =Assumptions!C32*(1-Assumptions!C43) -> 10500 | D30: =IF(C30=0,"-",C30/C$6) -> 0.010447761 | E30: =Assumptions!D32*(1-Assumptions!D43) -> 17500 | F30: =IF(E30=0,"-",E30/E$6) -> 0.0069651741 | G30: =Assumptions!E32*(1-Assumptions!E43) -> 30000 | H30: =IF(G30=0,"-",G30/G$6) -> 0.0059701493
B31: Licenses, Permits, Training | C31: =Assumptions!C33 -> 8000 | D31: =IF(C31=0,"-",C31/C$6) -> 0.007960199 | E31: =Assumptions!D33 -> 15000 | F31: =IF(E31=0,"-",E31/E$6) -> 0.0059701493 | G31: =Assumptions!E33 -> 25000 | H31: =IF(G31=0,"-",G31/G$6) -> 0.0049751244
B32: Miscellaneous | C32: =Assumptions!C34*(1-Assumptions!C44) -> 4800 | D32: =IF(C32=0,"-",C32/C$6) -> 0.0047761194 | E32: =Assumptions!D34*(1-Assumptions!D44) -> 8000 | F32: =IF(E32=0,"-",E32/E$6) -> 0.0031840796 | G32: =Assumptions!E34*(1-Assumptions!E44) -> 14400 | H32: =IF(G32=0,"-",G32/G$6) -> 0.0028656716
B33: Total G&A | C33: =SUM(C25:C32) -> 232800 | D33: =IF(C33=0,"-",C33/C$6) -> 0.23164179 | E33: =SUM(E25:E32) -> 368750 | F33: =IF(E33=0,"-",E33/E$6) -> 0.14676617 | G33: =SUM(G25:G32) -> 545400 | H33: =IF(G33=0,"-",G33/G$6) -> 0.10853731
B35: Total Operating Expenses | C35: =C13+C22+C33 -> 864945 | D35: =IF(C35=0,"-",C35/C$6) -> 0.86064179 | E35: =E13+E22+E33 -> 1901249.4 | F35: =IF(E35=0,"-",E35/E$6) -> 0.75671617 | G35: =G13+G22+G33 -> 3515175 | H35: =IF(G35=0,"-",G35/G$6) -> 0.69953731
B37: EBITDA | C37: =C6-C35 -> 140055 | D37: =IF(C37=0,"-",C37/C$6) -> 0.13935821 | E37: =E6-E35 -> 611250.62 | F37: =IF(E37=0,"-",E37/E$6) -> 0.24328383 | G37: =G6-G35 -> 1509825 | H37: =IF(G37=0,"-",G37/G$6) -> 0.30046269

Sheet AI Impact Summary
B2: AI Impact Summary — Baseline vs. AI-Enhanced
C4: $1M Tier | D4: $2.5M Tier | E4: $5M Tier
B5: Revenue
B6: Baseline Revenue | C6: ='Baseline P&L'!C6 -> 1000000 | D6: ='Baseline P&L'!E6 -> 2500000 | E6: ='Baseline P&L'!G6 -> 5000000
B7: AI-Enhanced Revenue | C7: ='AI-Enhanced P&L'!C6 -> 1005000 | D7: ='AI-Enhanced P&L'!E6 -> 2512500 | E7: ='AI-Enhanced P&L'!G6 -> 5025000
B8: Revenue Uplift | C8: =C7-C6 -> 5000 | D8: =D7-D6 -> 12500 | E8: =E7-E6 -> 25000
B10: Sales & Marketing Savings
B11: Baseline S&M | C11: ='Baseline P&L'!C22 -> 110000 | D11: ='Baseline P&L'!E22 -> 275000 | E11: ='Baseline P&L'!G22 -> 550000
B12: AI-Enhanced S&M | C12: ='AI-Enhanced P&L'!C22 -> 79395 | D12: ='AI-Enhanced P&L'!E22 -> 213436.88 | E12: ='AI-Enhanced P&L'!G22 -> 457275
B13: S&M Savings | C13: =C11-C12 -> 30605 | D13: =D11-D12 -> 61563.125 | E13: =E11-E12 -> 92725
B15: G&A Savings
B16: Baseline G&A | C16: ='Baseline P&L'!C33 -> 260000 | D16: ='Baseline P&L'!E33 -> 420000 | E16: ='Baseline P&L'!G33 -> 623000
B17: AI-Enhanced G&A | C17: ='AI-Enhanced P&L'!C33 -> 232800 | D17: ='AI-Enhanced P&L'!E33 -> 368750 | E17: ='AI-Enhanced P&L'!G33 -> 545400
B18: G&A Savings | C18: =C16-C17 -> 27200 | D18: =D16-D17 -> 51250 | E18: =E16-E17 -> 77600
B20: EBITDA Comparison
B21: Baseline EBITDA | C21: ='Baseline P&L'!C37 -> 80000 | D21: ='Baseline P&L'!E37 -> 492500 | E21: ='Baseline P&L'!G37 -> 1327000
B22: Baseline EBITDA Margin | C22: =IF('Baseline P&L'!C6=0,0,'Baseline P&L'!C37/'Baseline P&L'!C6) -> 0.08 | D22: =IF('Baseline P&L'!E6=0,0,'Baseline P&L'!E37/'Baseline P&L'!E6) -> 0.197 | E22: =IF('Baseline P&L'!G6=0,0,'Baseline P&L'!G37/'Baseline P&L'!G6) -> 0.2654
B23: AI-Enhanced EBITDA | C23: ='AI-Enhanced P&L'!C37 -> 140055 | D23: ='AI-Enhanced P&L'!E37 -> 611250.62 | E23: ='AI-Enhanced P&L'!G37 -> 1509825
B24: AI-Enhanced EBITDA Margin | C24: =IF('AI-Enhanced P&L'!C6=0,0,'AI-Enhanced P&L'!C37/'AI-Enhanced P&L'!C6) -> 0.13935821 | D24: =IF('AI-Enhanced P&L'!E6=0,0,'AI-Enhanced P&L'!E37/'AI-Enhanced P&L'!E6) -> 0.24328383 | E24: =IF('AI-Enhanced P&L'!G6=0,0,'AI-Enhanced P&L'!G37/'AI-Enhanced P&L'!G6) -> 0.30046269
B26: Total EBITDA Improvement ($) | C26: =C23-C21 -> 60055 | D26: =D23-D21 -> 118750.62 | E26: =E23-E21 -> 182825
B27: EBITDA Margin Improvement (pp) | C27: =IF('AI-Enhanced P&L'!C6=0,0,'AI-Enhanced P&L'!C37/'AI-Enhanced P&L'!C6)-IF('Baseline P&L'!C6=0,0,'Baseline P&L'!C37/'Baseline P&L'!C6) -> 0.059358209 | D27: =IF('AI-Enhanced P&L'!E6=0,0,'AI-Enhanced P&L'!E37/'AI-Enhanced P&L'!E6)-IF('Baseline P&L'!E6=0,0,'Baseline P&L'!E37/'Baseline P&L'!E6) -> 0.046283831 | E27: =IF('AI-Enhanced P&L'!G6=0,0,'AI-Enhanced P&L'!G37/'AI-Enhanced P&L'!G6)-IF('Baseline P&L'!G6=0,0,'Baseline P&L'!G37/'Baseline P&L'!G6) -> 0.035062687
